# SGE_BLOC2

# Verificación de la conexión a la base de datos

La siguiente imagen muestra la ejecución del script `connect.py`, donde se intenta conectar a una base de datos PostgreSQL llamada `the_bear`. 

Si la conexión es exitosa, se imprime el objeto de conexión. Si falla, se muestra un mensaje de error indicando el problema.

![Captura de la conexión]![baixa](https://github.com/user-attachments/assets/f558413f-285c-40c6-b873-fc33aafd0b17)

 Podem veure com obrim la connexió i la tanquem amb èxit, com


![Captura de pantalla 2025-02-08 154227](https://github.com/user-attachments/assets/e389222a-c1ac-4280-83b8-eb03f599c0a2)

PAS 6 Introduïm dades del csv clients a la BD, es possible perque em establit conexio amb la base de dades i hem creat la taula clients


![image](https://github.com/user-attachments/assets/20eb8644-9a1d-45bf-b2e5-c8b790aa86d2)

COMPROVEM LA TAULA CREAT


![Captura de pantalla 2025-02-08 153855](https://github.com/user-attachments/assets/e5dd050f-5dd3-4197-9fc0-4a0e69321df5)
PAS8 Agafa les dades de la taula clients i les mostra

![Captura de pantalla 2025-02-08 153946](https://github.com/user-attachments/assets/1fac91fb-a755-4a92-aa18-c65adfa02df3)
 El telefon s'ha actualitzat

![Captura de pantalla 2025-02-08 154037](https://github.com/user-attachments/assets/ce55d136-6943-4e13-ad68-ffb4c7c95d92)
Hem eliminat el USUARI Roger i ja no surt una vegada executem el main
